#include<iostream>
#include<exception>
using namespace std;
class Student :public exception{private:
	int total;
	public:
		const char std(){return ("check the whole students of class 10th is ");}
		void setstudent(){cout<<"total students is "<<total<<endl;}
		void settotal(int total){this->total=total;
		}
};
class Totalstudent{private:
	int total;
	public:
	Totalstudent(){total=0;}
	{cout<<"total student is zero"<<endl;}
	void data()
	{for(;;){total+=20;}
	cout<<"total student is "<<total<<endl;
	is(total>=40)
	}
	{overolltotal t}
	t.gettotal(total);
{
		throw t;}
};
int main(){ Totalstudent raj;
try{raj.data();}
catch(overolltotal t)
cout<<t.std<<endl;
t.setstudent();
return 0;
}



